Workbook

Sheet products
A1: sku | B1: product_name | C1: category | D1: base_unit | E1: specification | F1: unit_cost_cny | G1: safety_stock_qty | H1: expiry_warning_days | I1: storage_zone | J1: storage_note | K1: unit_weight_kg
A2: SKU001 | B2: 茉莉绿茶 | C2: 茶叶 | D2: 袋 | E2: 500g/袋 | F2: 79.76 | G2: 25 | H2: 30 | I2: DRY_FOOD | J2: 模拟未开封常温干燥储存；实际以标签和企业SOP为准 | K2: 0.5
A3: SKU002 | B3: 红茶 | C3: 茶叶 | D3: 袋 | E3: 500g/袋 | F3: 78.48 | G3: 25 | H3: 30 | I3: DRY_FOOD | J3: 模拟未开封常温干燥储存；实际以标签和企业SOP为准 | K3: 0.5
A4: SKU003 | B4: 乌龙茶 | C4: 茶叶 | D4: 袋 | E4: 500g/袋 | F4: 41.99 | G4: 25 | H4: 30 | I4: DRY_FOOD | J4: 模拟未开封常温干燥储存；实际以标签和企业SOP为准 | K4: 0.5
A5: SKU004 | B5: 四季春茶 | C5: 茶叶 | D5: 袋 | E5: 500g/袋 | F5: 70.39 | G5: 25 | H5: 30 | I5: DRY_FOOD | J5: 模拟未开封常温干燥储存；实际以标签和企业SOP为准 | K5: 0.5
A6: SKU005 | B6: 桂花乌龙 | C6: 茶叶 | D6: 袋 | E6: 500g/袋 | F6: 56.61 | G6: 25 | H6: 30 | I6: DRY_FOOD | J6: 模拟未开封常温干燥储存；实际以标签和企业SOP为准 | K6: 0.5
A7: SKU006 | B7: 焙火乌龙 | C7: 茶叶 | D7: 袋 | E7: 500g/袋 | F7: 30.07 | G7: 25 | H7: 30 | I7: DRY_FOOD | J7: 模拟未开封常温干燥储存；实际以标签和企业SOP为准 | K7: 0.5
A8: SKU007 | B8: 白桃乌龙 | C8: 茶叶 | D8: 袋 | E8: 500g/袋 | F8: 30.79 | G8: 25 | H8: 30 | I8: DRY_FOOD | J8: 模拟未开封常温干燥储存；实际以标签和企业SOP为准 | K8: 0.5
A9: SKU008 | B9: 普洱茶 | C9: 茶叶 | D9: 袋 | E9: 500g/袋 | F9: 72.54 | G9: 25 | H9: 30 | I9: DRY_FOOD | J9: 模拟未开封常温干燥储存；实际以标签和企业SOP为准 | K9: 0.5
A10: SKU009 | B10: 龙井茶 | C10: 茶叶 | D10: 袋 | E10: 500g/袋 | F10: 21.12 | G10: 25 | H10: 30 | I10: DRY_FOOD | J10: 模拟未开封常温干燥储存；实际以标签和企业SOP为准 | K10: 0.5
A11: SKU010 | B11: 栀子绿茶 | C11: 茶叶 | D11: 袋 | E11: 500g/袋 | F11: 29.05 | G11: 25 | H11: 30 | I11: DRY_FOOD | J11: 模拟未开封常温干燥储存；实际以标签和企业SOP为准 | K11: 0.5
A12: SKU011 | B12: 原味糖浆 | C12: 液体原料 | D12: 瓶 | E12: 1L/瓶 | F12: 24.06 | G12: 25 | H12: 30 | I12: DRY_FOOD | J12: 模拟未开封常温干燥储存；实际以标签和企业SOP为准 | K12: 1
A13: SKU012 | B13: 黑糖糖浆 | C13: 液体原料 | D13: 瓶 | E13: 1L/瓶 | F13: 77.96 | G13: 25 | H13: 30 | I13: DRY_FOOD | J13: 模拟未开封常温干燥储存；实际以标签和企业SOP为准 | K13: 1
... A31: SKU030 | B31: 纸巾 | C31: 包材 | D31: 包 | E31: 100张/包 | F31: 27.65 | G31: 40 | H31: 60 | I31: PACKAGING | J31: 模拟未开封常温干燥储存；实际以标签和企业SOP为准 | K31: 0.3

Sheet batches
A1: batch_id | B1: sku | C1: location_id | D1: production_date | E1: expiry_date | F1: available_from | G1: quality_status
A2: B0001 | B2: SKU001 | C2: L001 | D2: 46172 | E2: 46282 | F2: 46182 | G2: RELEASED
A3: B0002 | B3: SKU002 | C3: L002 | D3: 46172 | E3: 46252 | F3: 46182 | G3: RELEASED
A4: B0003 | B4: SKU003 | C4: L003 | D4: 46172 | E4: 46252 | F4: 46182 | G4: RELEASED
A5: B0004 | B5: SKU004 | C5: L004 | D5: 46172 | E5: 46282 | F5: 46182 | G5: RELEASED
A6: B0005 | B6: SKU005 | C6: L005 | D6: 46172 | E6: 46227 | F6: 46182 | G6: RELEASED
A7: B0006 | B7: SKU006 | C7: L006 | D7: 46172 | E7: 46362 | F7: 46182 | G7: RELEASED
A8: B0007 | B8: SKU007 | C8: L007 | D8: 46172 | E8: 46282 | F8: 46182 | G8: RELEASED
A9: B0008 | B9: SKU008 | C9: L008 | D9: 46172 | E9: 46227 | F9: 46182 | G9: RELEASED
A10: B0009 | B10: SKU009 | C10: L009 | D10: 46172 | E10: 46282 | F10: 46182 | G10: RELEASED
A11: B0010 | B11: SKU010 | C11: L010 | D11: 46172 | E11: 46242 | F11: 46182 | G11: RELEASED
A12: B0011 | B12: SKU011 | C12: L011 | D12: 46172 | E12: 46362 | F12: 46182 | G12: RELEASED
A13: B0012 | B13: SKU012 | C13: L012 | D13: 46172 | E13: 46252 | F13: 46182 | G13: RELEASED
... A225: B0224 | B225: SKU028 | C225: L028 | D225: 46256 | E225: 46631 | F225: 46266 | G225: RELEASED

Sheet movements
A1: movement_id | B1: document_id | C1: event_time | D1: movement_type | E1: sku | F1: batch_id | G1: location_id | H1: quantity | I1: order_line_id | J1: receipt_id
A2: M000001 | B2: D000001 | C2: 46182 | D2: OPENING | E2: SKU001 | F2: B0001 | G2: L001 | H2: 80
A3: M000002 | B3: D000002 | C3: 46182 | D3: OPENING | E3: SKU002 | F3: B0002 | G3: L002 | H3: 80
A4: M000003 | B4: D000003 | C4: 46182 | D4: OPENING | E4: SKU003 | F4: B0003 | G4: L003 | H4: 80
A5: M000004 | B5: D000004 | C5: 46182 | D5: OPENING | E5: SKU004 | F5: B0004 | G5: L004 | H5: 80
A6: M000005 | B6: D000005 | C6: 46182 | D6: OPENING | E6: SKU005 | F6: B0005 | G6: L005 | H6: 80
A7: M000006 | B7: D000006 | C7: 46182 | D7: OPENING | E7: SKU006 | F7: B0006 | G7: L006 | H7: 80
A8: M000007 | B8: D000007 | C8: 46182 | D8: OPENING | E8: SKU007 | F8: B0007 | G8: L007 | H8: 80
A9: M000008 | B9: D000008 | C9: 46182 | D9: OPENING | E9: SKU008 | F9: B0008 | G9: L008 | H9: 80
A10: M000009 | B10: D000009 | C10: 46182 | D10: OPENING | E10: SKU009 | F10: B0009 | G10: L009 | H10: 80
A11: M000010 | B11: D000010 | C11: 46182 | D11: OPENING | E11: SKU010 | F11: B0010 | G11: L010 | H11: 80
A12: M000011 | B12: D000011 | C12: 46182 | D12: OPENING | E12: SKU011 | F12: B0011 | G12: L011 | H12: 80
A13: M000012 | B13: D000012 | C13: 46182 | D13: OPENING | E13: SKU012 | F13: B0012 | G13: L012 | H13: 80
... A31: M000030 | B31: D000030 | C31: 46182 | D31: OPENING | E31: SKU030 | F31: B0030 | G31: L030 | H31: 240
A32: M000031 | B32: D000031 | C32: 46182.583 | D32: ISSUE | E32: SKU002 | F32: B0002 | G32: L002 | H32: 1 | I32: O00001
A33: M000032 | B33: D000032 | C33: 46182.583 | D33: ISSUE | E33: SKU004 | F33: B0004 | G33: L004 | H33: 1 | I33: O00002
A34: M000033 | B34: D000033 | C34: 46182.583 | D34: ISSUE | E34: SKU017 | F34: B0017 | G34: L017 | H34: 2 | I34: O00003
A35: M000034 | B35: D000034 | C35: 46182.583 | D35: ISSUE | E35: SKU022 | F35: B0022 | G35: L022 | H35: 1 | I35: O00004
A36: M000035 | B36: D000035 | C36: 46182.583 | D36: ISSUE | E36: SKU026 | F36: B0026 | G36: L026 | H36: 2 | I36: O00005
A37: M000036 | B37: D000036 | C37: 46182.583 | D37: ISSUE | E37: SKU001 | F37: B0001 | G37: L001 | H37: 3 | I37: O00006
A38: M000037 | B38: D000037 | C38: 46182.583 | D38: ISSUE | E38: SKU002 | F38: B0002 | G38: L002 | H38: 5 | I38: O00007
A39: M000038 | B39: D000038 | C39: 46182.583 | D39: ISSUE | E39: SKU003 | F39: B0003 | G39: L003 | H39: 4 | I39: O00008
A40: M000039 | B40: D000039 | C40: 46182.583 | D40: ISSUE | E40: SKU004 | F40: B0004 | G40: L004 | H40: 1 | I40: O00009
A41: M000040 | B41: D000040 | C41: 46182.583 | D41: ISSUE | E41: SKU005 | F41: B0005 | G41: L005 | H41: 3 | I41: O00010
A42: M000041 | B42: D000041 | C42: 46182.583 | D42: ISSUE | E42: SKU011 | F42: B0011 | G42: L011 | H42: 1 | I42: O00011
A43: M000042 | B43: D000042 | C43: 46182.583 | D43: ISSUE | E43: SKU024 | F43: B0024 | G43: L024 | H43: 1 | I43: O00012
... A362: M000361 | B362: D000361 | C362: 46188.583 | D362: ISSUE | E362: SKU028 | F362: B0028 | G362: L028 | H362: 2 | I362: O00334
A363: M000362 | B363: D000362 | C363: 46189.333 | D363: RECEIPT | E363: SKU001 | F363: B0031 | G363: L001 | H363: 80 | J363: R0001
A364: M000363 | B364: D000363 | C364: 46189.333 | D364: RECEIPT | E364: SKU002 | F364: B0032 | G364: L002 | H364: 81 | J364: R0002
A365: M000364 | B365: D000364 | C365: 46189.333 | D365: RECEIPT | E365: SKU003 | F365: B0033 | G365: L003 | H365: 67 | J365: R0003
A366: M000365 | B366: D000365 | C366: 46189.333 | D366: RECEIPT | E366: SKU004 | F366: B0034 | G366: L004 | H366: 68 | J366: R0004
A367: M000366 | B367: D000366 | C367: 46189.333 | D367: RECEIPT | E367: SKU005 | F367: B0035 | G367: L005 | H367: 99 | J367: R0005
A368: M000367 | B368: D000367 | C368: 46189.333 | D368: RECEIPT | E368: SKU006 | F368: B0036 | G368: L006 | H368: 78 | J368: R0006
A369: M000368 | B369: D000368 | C369: 46189.333 | D369: RECEIPT | E369: SKU007 | F369: B0037 | G369: L007 | H369: 99 | J369: R0007
A370: M000369 | B370: D000369 | C370: 46189.333 | D370: RECEIPT | E370: SKU008 | F370: B0038 | G370: L008 | H370: 92 | J370: R0008
A371: M000370 | B371: D000370 | C371: 46189.333 | D371: RECEIPT | E371: SKU009 | F371: B0039 | G371: L009 | H371: 76 | J371: R0009
A372: M000371 | B372: D000371 | C372: 46189.333 | D372: RECEIPT | E372: SKU010 | F372: B0040 | G372: L010 | H372: 86 | J372: R0010
A373: M000372 | B373: D000372 | C373: 46189.333 | D373: RECEIPT | E373: SKU011 | F373: B0041 | G373: L011 | H373: 80 | J373: R0011
A374: M000373 | B374: D000373 | C374: 46189.333 | D374: RECEIPT | E374: SKU012 | F374: B0042 | G374: L012 | H374: 60 | J374: R0012
... A390: M000389 | B390: D000389 | C390: 46189.333 | D390: RECEIPT | E390: SKU028 | F390: B0058 | G390: L028 | H390: 71 | J390: R0028
...

Sheet stores
A1: store_id | B1: store_name | C1: demand_factor
A2: S1 | B2: 模拟门店1 | C2: 0.8
A3: S2 | B3: 模拟门店2 | C3: 1
A4: S3 | B4: 模拟门店3 | C4: 1.2
A5: S4 | B5: 模拟门店4 | C5: 1.4
A6: S5 | B6: 模拟门店5 | C6: 0.9

Sheet order_lines
A1: order_line_id | B1: order_id | C1: order_time | D1: store_id | E1: sku | F1: requested_qty | G1: promised_ship_time | H1: actual_ship_time
A2: O00001 | B2: ORD000S1 | C2: 46182.417 | D2: S1 | E2: SKU002 | F2: 1 | G2: 46182.75 | H2: 46182.583
A3: O00002 | B3: ORD000S1 | C3: 46182.417 | D3: S1 | E3: SKU004 | F3: 1 | G3: 46182.75 | H3: 46182.583
A4: O00003 | B4: ORD000S1 | C4: 46182.417 | D4: S1 | E4: SKU017 | F4: 2 | G4: 46182.75 | H4: 46182.583
A5: O00004 | B5: ORD000S1 | C5: 46182.417 | D5: S1 | E5: SKU022 | F5: 1 | G5: 46182.75 | H5: 46182.583
A6: O00005 | B6: ORD000S1 | C6: 46182.417 | D6: S1 | E6: SKU026 | F6: 2 | G6: 46182.75 | H6: 46182.583
A7: O00006 | B7: ORD000S2 | C7: 46182.417 | D7: S2 | E7: SKU001 | F7: 3 | G7: 46182.75 | H7: 46182.583
A8: O00007 | B8: ORD000S2 | C8: 46182.417 | D8: S2 | E8: SKU002 | F8: 5 | G8: 46182.75 | H8: 46182.583
A9: O00008 | B9: ORD000S2 | C9: 46182.417 | D9: S2 | E9: SKU003 | F9: 4 | G9: 46182.75 | H9: 46182.583
A10: O00009 | B10: ORD000S2 | C10: 46182.417 | D10: S2 | E10: SKU004 | F10: 1 | G10: 46182.75 | H10: 46182.583
A11: O00010 | B11: ORD000S2 | C11: 46182.417 | D11: S2 | E11: SKU005 | F11: 3 | G11: 46182.75 | H11: 46182.583
A12: O00011 | B12: ORD000S2 | C12: 46182.417 | D12: S2 | E12: SKU011 | F12: 1 | G12: 46182.75 | H12: 46182.583
A13: O00012 | B13: ORD000S2 | C13: 46182.417 | D13: S2 | E13: SKU024 | F13: 1 | G13: 46182.75 | H13: 46182.583
... A286: O00285 | B286: ORD006S2 | C286: 46188.417 | D286: S2 | E286: SKU002 | F286: 5 | G286: 46188.75 | H286: 46188.583
A287: O00286 | B287: ORD006S2 | C287: 46188.417 | D287: S2 | E287: SKU003 | F287: 1 | G287: 46188.75
A288: O00287 | B288: ORD006S2 | C288: 46188.417 | D288: S2 | E288: SKU005 | F288: 1 | G288: 46188.75 | H288: 46188.583
A289: O00288 | B289: ORD006S2 | C289: 46188.417 | D289: S2 | E289: SKU006 | F289: 5 | G289: 46188.75 | H289: 46188.583
A290: O00289 | B290: ORD006S2 | C290: 46188.417 | D290: S2 | E290: SKU007 | F290: 3 | G290: 46188.75 | H290: 46188.583
A291: O00290 | B291: ORD006S2 | C291: 46188.417 | D291: S2 | E291: SKU009 | F291: 5 | G291: 46188.75 | H291: 46188.583
A292: O00291 | B292: ORD006S2 | C292: 46188.417 | D292: S2 | E292: SKU014 | F292: 5 | G292: 46188.75 | H292: 46188.583
A293: O00292 | B293: ORD006S2 | C293: 46188.417 | D293: S2 | E293: SKU015 | F293: 1 | G293: 46188.75 | H293: 46188.583
A294: O00293 | B294: ORD006S2 | C294: 46188.417 | D294: S2 | E294: SKU017 | F294: 3 | G294: 46188.75 | H294: 46188.583
A295: O00294 | B295: ORD006S2 | C295: 46188.417 | D295: S2 | E295: SKU020 | F295: 2 | G295: 46188.75 | H295: 46188.583
A296: O00295 | B296: ORD006S2 | C296: 46188.417 | D296: S2 | E296: SKU021 | F296: 3 | G296: 46188.75 | H296: 46188.583
A297: O00296 | B297: ORD006S2 | C297: 46188.417 | D297: S2 | E297: SKU025 | F297: 2 | G297: 46188.75 | H297: 46188.583
A298: O00297 | B298: ORD006S2 | C298: 46188.417 | D298: S2 | E298: SKU027 | F298: 2 | G298: 46188.75 | H298: 46188.583
A299: O00298 | B299: ORD006S3 | C299: 46188.417 | D299: S3 | E299: SKU001 | F299: 6 | G299: 46188.75 | H299: 46188.583
A300: O00299 | B300: ORD006S3 | C300: 46188.417 | D300: S3 | E300: SKU002 | F300: 1 | G300: 46188.75 | H300: 46188.583
A301: O00300 | B301: ORD006S3 | C301: 46188.417 | D301: S3 | E301: SKU003 | F301: 2 | G301: 46188.75
A302: O00301 | B302: ORD006S3 | C302: 46188.417 | D302: S3 | E302: SKU004 | F302: 6 | G302: 46188.75 | H302: 46188.583
A303: O00302 | B303: ORD006S3 | C303: 46188.417 | D303: S3 | E303: SKU005 | F303: 2 | G303: 46188.75 | H303: 46188.583
A304: O00303 | B304: ORD006S3 | C304: 46188.417 | D304: S3 | E304: SKU006 | F304: 5 | G304: 46188.75 | H304: 46188.583
A305: O00304 | B305: ORD006S3 | C305: 46188.417 | D305: S3 | E305: SKU007 | F305: 6 | G305: 46188.75 | H305: 46188.583
A306: O00305 | B306: ORD006S3 | C306: 46188.417 | D306: S3 | E306: SKU011 | F306: 6 | G306: 46188.75 | H306: 46188.583
A307: O00306 | B307: ORD006S3 | C307: 46188.417 | D307: S3 | E307: SKU013 | F307: 4 | G307: 46188.75 | H307: 46188.583
A308: O00307 | B308: ORD006S3 | C308: 46188.417 | D308: S3 | E308: SKU014 | F308: 2 | G308: 46188.75 | H308: 46188.583
A309: O00308 | B309: ORD006S3 | C309: 46188.417 | D309: S3 | E309: SKU018 | F309: 6 | G309: 46188.75 | H309: 46188.583
A310: O00309 | B310: ORD006S3 | C310: 46188.417 | D310: S3 | E310: SKU021 | F310: 1 | G310: 46188.75 | H310: 46188.583
A311: O00310 | B311: ORD006S3 | C311: 46188.417 | D311: S3 | E311: SKU023 | F311: 4 | G311: 46188.75 | H311: 46188.583
A312: O00311 | B312: ORD006S4 | C312: 46188.417 | D312: S4 | E312: SKU001 | F312: 3 | G312: 46188.75 | H312: 46188.583
...

Sheet stock_counts
A1: count_line_id | B1: count_time | C1: sku | D1: batch_id | E1: location_id | F1: book_qty_snapshot | G1: first_count_qty | H1: recount_qty | I1: investigation_status | J1: 盘点差异 | K1: 盘点结果 | L1: 差异金额
A2: C0001 | B2: 46211.833 | C2: SKU007 | D2: B0007 | E2: L007 | F2: 56 | G2: 54 | H2: 54 | I2: OPEN | J2: =H2-F2 -> -2 | K2: =IF(J2=0,"一致",IF(J2>0,"盘盈","盘亏")) -> 盘亏 | L2: =J2*VLOOKUP(stock_counts__2[[#This Row],[sku]],products!A:F,6,0) -> -61.58
A3: C0002 | B3: 46211.833 | C3: SKU009 | D3: B0009 | E3: L009 | F3: 48 | G3: 48 | H3: 48 | I3: MATCHED | J3: =H3-F3 -> 0 | K3: =IF(J3=0,"一致",IF(J3>0,"盘盈","盘亏")) -> 一致 | L3: =J3*VLOOKUP(stock_counts__2[[#This Row],[sku]],products!A:F,6,0) -> 0
A4: C0003 | B4: 46211.833 | C4: SKU010 | D4: B0010 | E4: L010 | F4: 80 | G4: 80 | H4: 80 | I4: MATCHED | J4: =H4-F4 -> 0 | K4: =IF(J4=0,"一致",IF(J4>0,"盘盈","盘亏")) -> 一致 | L4: =J4*VLOOKUP(stock_counts__2[[#This Row],[sku]],products!A:F,6,0) -> 0
A5: C0004 | B5: 46211.833 | C5: SKU012 | D5: B0012 | E5: L012 | F5: 8 | G5: 8 | H5: 8 | I5: MATCHED | J5: =H5-F5 -> 0 | K5: =IF(J5=0,"一致",IF(J5>0,"盘盈","盘亏")) -> 一致 | L5: =J5*VLOOKUP(stock_counts__2[[#This Row],[sku]],products!A:F,6,0) -> 0
A6: C0005 | B6: 46211.833 | C6: SKU013 | D6: B0013 | E6: L013 | F6: 66 | G6: 66 | H6: 66 | I6: MATCHED | J6: =H6-F6 -> 0 | K6: =IF(J6=0,"一致",IF(J6>0,"盘盈","盘亏")) -> 一致 | L6: =J6*VLOOKUP(stock_counts__2[[#This Row],[sku]],products!A:F,6,0) -> 0
A7: C0006 | B7: 46211.833 | C7: SKU015 | D7: B0015 | E7: L015 | F7: 35 | G7: 35 | H7: 35 | I7: MATCHED | J7: =H7-F7 -> 0 | K7: =IF(J7=0,"一致",IF(J7>0,"盘盈","盘亏")) -> 一致 | L7: =J7*VLOOKUP(stock_counts__2[[#This Row],[sku]],products!A:F,6,0) -> 0
A8: C0007 | B8: 46211.833 | C8: SKU018 | D8: B0018 | E8: L018 | F8: 56 | G8: 56 | H8: 56 | I8: MATCHED | J8: =H8-F8 -> 0 | K8: =IF(J8=0,"一致",IF(J8>0,"盘盈","盘亏")) -> 一致 | L8: =J8*VLOOKUP(stock_counts__2[[#This Row],[sku]],products!A:F,6,0) -> 0
A9: C0008 | B9: 46211.833 | C9: SKU029 | D9: B0029 | E9: L029 | F9: 239 | G9: 239 | H9: 239 | I9: MATCHED | J9: =H9-F9 -> 0 | K9: =IF(J9=0,"一致",IF(J9>0,"盘盈","盘亏")) -> 一致 | L9: =J9*VLOOKUP(stock_counts__2[[#This Row],[sku]],products!A:F,6,0) -> 0
A10: C0009 | B10: 46211.833 | C10: SKU030 | D10: B0030 | E10: L030 | F10: 240 | G10: 240 | H10: 240 | I10: MATCHED | J10: =H10-F10 -> 0 | K10: =IF(J10=0,"一致",IF(J10>0,"盘盈","盘亏")) -> 一致 | L10: =J10*VLOOKUP(stock_counts__2[[#This Row],[sku]],products!A:F,6,0) -> 0
A11: C0010 | B11: 46211.833 | C11: SKU008 | D11: B0038 | E11: L008 | F11: 50 | G11: 50 | H11: 50 | I11: MATCHED | J11: =H11-F11 -> 0 | K11: =IF(J11=0,"一致",IF(J11>0,"盘盈","盘亏")) -> 一致 | L11: =J11*VLOOKUP(stock_counts__2[[#This Row],[sku]],products!A:F,6,0) -> 0
A12: C0011 | B12: 46211.833 | C12: SKU009 | D12: B0039 | E12: L009 | F12: 21 | G12: 21 | H12: 21 | I12: MATCHED | J12: =H12-F12 -> 0 | K12: =IF(J12=0,"一致",IF(J12>0,"盘盈","盘亏")) -> 一致 | L12: =J12*VLOOKUP(stock_counts__2[[#This Row],[sku]],products!A:F,6,0) -> 0
A13: C0012 | B13: 46211.833 | C13: SKU010 | D13: B0040 | E13: L010 | F13: 86 | G13: 84 | H13: 84 | I13: OPEN | J13: =H13-F13 -> -2 | K13: =IF(J13=0,"一致",IF(J13>0,"盘盈","盘亏")) -> 盘亏 | L13: =J13*VLOOKUP(stock_counts__2[[#This Row],[sku]],products!A:F,6,0) -> -58.1
... A197: C0196 | B197: 46271.833 | C197: SKU028 | D197: B0224 | E197: L028 | F197: 66 | G197: 66 | H197: 66 | I197: MATCHED | J197: =H197-F197 -> 0 | K197: =IF(J197=0,"一致",IF(J197>0,"盘盈","盘亏")) -> 一致 | L197: =J197*VLOOKUP(stock_counts__2[[#This Row],[sku]],products!A:F,6,0) -> 0

Sheet 每日库存表
A1: SKU | B1: 46182 | C1: =B1+1 -> 46183 | D1: =C1+1 -> 46184 | E1: =D1+1 -> 46185 | F1: =E1+1 -> 46186 | G1: =F1+1 -> 46187 | H1: =G1+1 -> 46188 | I1: =H1+1 -> 46189 | J1: =I1+1 -> 46190 | ... CM1: =CL1+1 -> 46271 | CN1: 平均库存 | CO1: 90天出库量 | CP1: 周转次数 | CQ1: 周转天数
A2: SKU001 | B2: =SUMIFS(movements!$H:$H,movements!$E:$E,$A2,movements!$D:$D,"OPENING",movements!$C:$C,"<"&B$1+1)+SUMIFS(movements!$H:$H,movements!$E:$E,$A2,movements!$D:$D,"RECEIPT",movements!$C:$C,"<"&B$1+1)-SUMIFS(movements!$H:$H,movements!$E:$E,$A2,movements!$D:$D,"ISSUE",movements!$C:$C,"<"&B$1+1) -> 77 | C2: =SUMIFS(movements!$H:$H,movements!$E:$E,$A2,movements!$D:$D,"OPENING",movements!$C:$C,"<"&C$1+1)+SUMIFS(movements!$H:$H,movements!$E:$E,$A2,movements!$D:$D,"RECEIPT",movements!$C:$C,"<"&C$1+1)-SUMIFS(movements!$H:$H,movements!$E:$E,$A2,movements!$D:$D,"ISSUE",movements!$C:$C,"<"&C$1+1) -> 66 | D2: =SUMIFS(movements!$H:$H,movements!$E:$E,$A2,movements!$D:$D,"OPENING",movements!$C:$C,"<"&D$1+1)+SUMIFS(movements!$H:$H,movements!$E:$E,$A2,movements!$D:$D,"RECEIPT",movements!$C:$C,"<"&D$1+1)-SUMIFS(movements!$H:$H,movements!$E:$E,$A2,movements!$D:$D,"ISSUE",movements!$C:$C,"<"&D$1+1) -> 58 | E2: =SUMIFS(movements!$H:$H,movements!$E:$E,$A2,movements!$D:$D,"OPENING",movements!$C:$C,"<"&E$1+1)+SUMIFS(movements!$H:$H,movements!$E:$E,$A2,movements!$D:$D,"RECEIPT",movements!$C:$C,"<"&E$1+1)-SUMIFS(movements!$H:$H,movements!$E:$E,$A2,movements!$D:$D,"ISSUE",movements!$C:$C,"<"&E$1+1) -> 43 | F2: =SUMIFS(movements!$H:$H,movements!$E:$E,$A2,movements!$D:$D,"OPENING",movements!$C:$C,"<"&F$1+1)+SUMIFS(movements!$H:$H,movements!$E:$E,$A2,movements!$D:$D,"RECEIPT",movements!$C:$C,"<"&F$1+1)-SUMIFS(movements!$H:$H,movements!$E:$E,$A2,movements!$D:$D,"ISSUE",movements!$C:$C,"<"&F$1+1) -> 33 | G2: =SUMIFS(movements!$H:$H,movements!$E:$E,$A2,movements!$D:$D,"OPENING",movements!$C:$C,"<"&G$1+1)+SUMIFS(movements!$H:$H,movements!$E:$E,$A2,movements!$D:$D,"RECEIPT",movements!$C:$C,"<"&G$1+1)-SUMIFS(movements!$H:$H,movements!$E:$E,$A2,movements!$D:$D,"ISSUE",movements!$C:$C,"<"&G$1+1) -> 24 | H2: =SUMIFS(movements!$H:$H,movements!$E:$E,$A2,movements!$D:$D,"OPENING",movements!$C:$C,"<"&H$1+1)+SUMIFS(movements!$H:$H,movements!$E:$E,$A2,movements!$D:$D,"RECEIPT",movements!$C:$C,"<"&H$1+1)-SUMIFS(movements!$H:$H,movements!$E:$E,$A2,movements!$D:$D,"ISSUE",movements!$C:$C,"<"&H$1+1) -> 8 | I2: =SUMIFS(movements!$H:$H,movements!$E:$E,$A2,movements!$D:$D,"OPENING",movements!$C:$C,"<"&I$1+1)+SUMIFS(movements!$H:$H,movements!$E:$E,$A2,movements!$D:$D,"RECEIPT",movements!$C:$C,"<"&I$1+1)-SUMIFS(movements!$H:$H,movements!$E:$E,$A2,movements!$D:$D,"ISSUE",movements!$C:$C,"<"&I$1+1) -> 81 | ... CM2: =SUMIFS(movements!$H:$H,movements!$E:$E,$A2,movements!$D:$D,"OPENING",movements!$C:$C,"<"&CM$1+1)+SUMIFS(movements!$H:$H,movements!$E:$E,$A2,movements!$D:$D,"RECEIPT",movements!$C:$C,"<"&CM$1+1)-SUMIFS(movements!$H:$H,movements!$E:$E,$A2,movements!$D:$D,"ISSUE",movements!$C:$C,"<"&CM$1+1) -> 51 | CN2: =AVERAGE(B2:CM2) -> 47.311111 | CO2: =SUMIFS(movements!$H:$H,movements!$E:$E,$A2,movements!$D:$D,"ISSUE",movements!$C:$C,">="&$B$1,movements!$C:$C,"<"&($CM$1+1)) -> 777 | CP2: =IF(CN2=0,"无法计算",CO2/CN2) -> 16.423203 | CQ2: =IF(CO2=0,"期间无出库",IF(CN2=0,"无法计算",90/CP2)) -> 5.4800515
A3: SKU002 | B3: =SUMIFS(movements!$H:$H,movements!$E:$E,$A3,movements!$D:$D,"OPENING",movements!$C:$C,"<"&B$1+1)+SUMIFS(movements!$H:$H,movements!$E:$E,$A3,movements!$D:$D,"RECEIPT",movements!$C:$C,"<"&B$1+1)-SUMIFS(movements!$H:$H,movements!$E:$E,$A3,movements!$D:$D,"ISSUE",movements!$C:$C,"<"&B$1+1) -> 74 | C3: =SUMIFS(movements!$H:$H,movements!$E:$E,$A3,movements!$D:$D,"OPENING",movements!$C:$C,"<"&C$1+1)+SUMIFS(movements!$H:$H,movements!$E:$E,$A3,movements!$D:$D,"RECEIPT",movements!$C:$C,"<"&C$1+1)-SUMIFS(movements!$H:$H,movements!$E:$E,$A3,movements!$D:$D,"ISSUE",movements!$C:$C,"<"&C$1+1) -> 70 | D3: =SUMIFS(movements!$H:$H,movements!$E:$E,$A3,movements!$D:$D,"OPENING",movements!$C:$C,"<"&D$1+1)+SUMIFS(movements!$H:$H,movements!$E:$E,$A3,movements!$D:$D,"RECEIPT",movements!$C:$C,"<"&D$1+1)-SUMIFS(movements!$H:$H,movements!$E:$E,$A3,movements!$D:$D,"ISSUE",movements!$C:$C,"<"&D$1+1) -> 61 | E3: =SUMIFS(movements!$H:$H,movements!$E:$E,$A3,movements!$D:$D,"OPENING",movements!$C:$C,"<"&E$1+1)+SUMIFS(movements!$H:$H,movements!$E:$E,$A3,movements!$D:$D,"RECEIPT",movements!$C:$C,"<"&E$1+1)-SUMIFS(movements!$H:$H,movements!$E:$E,$A3,movements!$D:$D,"ISSUE",movements!$C:$C,"<"&E$1+1) -> 55 | F3: =SUMIFS(movements!$H:$H,movements!$E:$E,$A3,movements!$D:$D,"OPENING",movements!$C:$C,"<"&F$1+1)+SUMIFS(movements!$H:$H,movements!$E:$E,$A3,movements!$D:$D,"RECEIPT",movements!$C:$C,"<"&F$1+1)-SUMIFS(movements!$H:$H,movements!$E:$E,$A3,movements!$D:$D,"ISSUE",movements!$C:$C,"<"&F$1+1) -> 52 | G3: =SUMIFS(movements!$H:$H,movements!$E:$E,$A3,movements!$D:$D,"OPENING",movements!$C:$C,"<"&G$1+1)+SUMIFS(movements!$H:$H,movements!$E:$E,$A3,movements!$D:$D,"RECEIPT",movements!$C:$C,"<"&G$1+1)-SUMIFS(movements!$H:$H,movements!$E:$E,$A3,movements!$D:$D,"ISSUE",movements!$C:$C,"<"&G$1+1) -> 38 | H3: =SUMIFS(movements!$H:$H,movements!$E:$E,$A3,movements!$D:$D,"OPENING",movements!$C:$C,"<"&H$1+1)+SUMIFS(movements!$H:$H,movements!$E:$E,$A3,movements!$D:$D,"RECEIPT",movements!$C:$C,"<"&H$1+1)-SUMIFS(movements!$H:$H,movements!$E:$E,$A3,movements!$D:$D,"ISSUE",movements!$C:$C,"<"&H$1+1) -> 21 | I3: =SUMIFS(movements!$H:$H,movements!$E:$E,$A3,movements!$D:$D,"OPENING",movements!$C:$C,"<"&I$1+1)+SUMIFS(movements!$H:$H,movements!$E:$E,$A3,movements!$D:$D,"RECEIPT",movements!$C:$C,"<"&I$1+1)-SUMIFS(movements!$H:$H,movements!$E:$E,$A3,movements!$D:$D,"ISSUE",movements!$C:$C,"<"&I$1+1) -> 96 | ... CM3: =SUMIFS(movements!$H:$H,movements!$E:$E,$A3,movements!$D:$D,"OPENING",movements!$C:$C,"<"&CM$1+1)+SUMIFS(movements!$H:$H,movements!$E:$E,$A3,movements!$D:$D,"RECEIPT",movements!$C:$C,"<"&CM$1+1)-SUMIFS(movements!$H:$H,movements!$E:$E,$A3,movements!$D:$D,"ISSUE",movements!$C:$C,"<"&CM$1+1) -> 47 | CN3: =AVERAGE(B3:CM3) -> 97.311111 | CO3: =SUMIFS(movements!$H:$H,movements!$E:$E,$A3,movements!$D:$D,"ISSUE",movements!$C:$C,">="&$B$1,movements!$C:$C,"<"&($CM$1+1)) -> 933 | CP3: =IF(CN3=0,"无法计算",CO3/CN3) -> 9.5878054 | CQ3: =IF(CO3=0,"期间无出库",IF(CN3=0,"无法计算",90/CP3)) -> 9.3869239
A4: SKU003 | B4: =SUMIFS(movements!$H:$H,movements!$E:$E,$A4,movements!$D:$D,"OPENING",movements!$C:$C,"<"&B$1+1)+SUMIFS(movements!$H:$H,movements!$E:$E,$A4,movements!$D:$D,"RECEIPT",movements!$C:$C,"<"&B$1+1)-SUMIFS(movements!$H:$H,movements!$E:$E,$A4,movements!$D:$D,"ISSUE",movements!$C:$C,"<"&B$1+1) -> 63 | C4: =SUMIFS(movements!$H:$H,movements!$E:$E,$A4,movements!$D:$D,"OPENING",movements!$C:$C,"<"&C$1+1)+SUMIFS(movements!$H:$H,movements!$E:$E,$A4,movements!$D:$D,"RECEIPT",movements!$C:$C,"<"&C$1+1)-SUMIFS(movements!$H:$H,movements!$E:$E,$A4,movements!$D:$D,"ISSUE",movements!$C:$C,"<"&C$1+1) -> 53 | D4: =SUMIFS(movements!$H:$H,movements!$E:$E,$A4,movements!$D:$D,"OPENING",movements!$C:$C,"<"&D$1+1)+SUMIFS(movements!$H:$H,movements!$E:$E,$A4,movements!$D:$D,"RECEIPT",movements!$C:$C,"<"&D$1+1)-SUMIFS(movements!$H:$H,movements!$E:$E,$A4,movements!$D:$D,"ISSUE",movements!$C:$C,"<"&D$1+1) -> 41 | E4: =SUMIFS(movements!$H:$H,movements!$E:$E,$A4,movements!$D:$D,"OPENING",movements!$C:$C,"<"&E$1+1)+SUMIFS(movements!$H:$H,movements!$E:$E,$A4,movements!$D:$D,"RECEIPT",movements!$C:$C,"<"&E$1+1)-SUMIFS(movements!$H:$H,movements!$E:$E,$A4,movements!$D:$D,"ISSUE",movements!$C:$C,"<"&E$1+1) -> 31 | F4: =SUMIFS(movements!$H:$H,movements!$E:$E,$A4,movements!$D:$D,"OPENING",movements!$C:$C,"<"&F$1+1)+SUMIFS(movements!$H:$H,movements!$E:$E,$A4,movements!$D:$D,"RECEIPT",movements!$C:$C,"<"&F$1+1)-SUMIFS(movements!$H:$H,movements!$E:$E,$A4,movements!$D:$D,"ISSUE",movements!$C:$C,"<"&F$1+1) -> 21 | G4: =SUMIFS(movements!$H:$H,movements!$E:$E,$A4,movements!$D:$D,"OPENING",movements!$C:$C,"<"&G$1+1)+SUMIFS(movements!$H:$H,movements!$E:$E,$A4,movements!$D:$D,"RECEIPT",movements!$C:$C,"<"&G$1+1)-SUMIFS(movements!$H:$H,movements!$E:$E,$A4,movements!$D:$D,"ISSUE",movements!$C:$C,"<"&G$1+1) -> 0 | H4: =SUMIFS(movements!$H:$H,movements!$E:$E,$A4,movements!$D:$D,"OPENING",movements!$C:$C,"<"&H$1+1)+SUMIFS(movements!$H:$H,movements!$E:$E,$A4,movements!$D:$D,"RECEIPT",movements!$C:$C,"<"&H$1+1)-SUMIFS(movements!$H:$H,movements!$E:$E,$A4,movements!$D:$D,"ISSUE",movements!$C:$C,"<"&H$1+1) -> 0 | I4: =SUMIFS(movements!$H:$H,movements!$E:$E,$A4,movements!$D:$D,"OPENING",movements!$C:$C,"<"&I$1+1)+SUMIFS(movements!$H:$H,movements!$E:$E,$A4,movements!$D:$D,"RECEIPT",movements!$C:$C,"<"&I$1+1)-SUMIFS(movements!$H:$H,movements!$E:$E,$A4,movements!$D:$D,"ISSUE",movements!$C:$C,"<"&I$1+1) -> 49 | ... CM4: =SUMIFS(movements!$H:$H,movements!$E:$E,$A4,movements!$D:$D,"OPENING",movements!$C:$C,"<"&CM$1+1)+SUMIFS(movements!$H:$H,movements!$E:$E,$A4,movements!$D:$D,"RECEIPT",movements!$C:$C,"<"&CM$1+1)-SUMIFS(movements!$H:$H,movements!$E:$E,$A4,movements!$D:$D,"ISSUE",movements!$C:$C,"<"&CM$1+1) -> 21 | CN4: =AVERAGE(B4:CM4) -> 39.255556 | CO4: =SUMIFS(movements!$H:$H,movements!$E:$E,$A4,movements!$D:$D,"ISSUE",movements!$C:$C,">="&$B$1,movements!$C:$C,"<"&($CM$1+1)) -> 984 | CP4: =IF(CN4=0,"无法计算",CO4/CN4) -> 25.066516 | CQ4: =IF(CO4=0,"期间无出库",IF(CN4=0,"无法计算",90/CP4)) -> 3.5904472
A5: SKU004 | B5: =SUMIFS(movements!$H:$H,movements!$E:$E,$A5,movements!$D:$D,"OPENING",movements!$C:$C,"<"&B$1+1)+SUMIFS(movements!$H:$H,movements!$E:$E,$A5,movements!$D:$D,"RECEIPT",movements!$C:$C,"<"&B$1+1)-SUMIFS(movements!$H:$H,movements!$E:$E,$A5,movements!$D:$D,"ISSUE",movements!$C:$C,"<"&B$1+1) -> 70 | C5: =SUMIFS(movements!$H:$H,movements!$E:$E,$A5,movements!$D:$D,"OPENING",movements!$C:$C,"<"&C$1+1)+SUMIFS(movements!$H:$H,movements!$E:$E,$A5,movements!$D:$D,"RECEIPT",movements!$C:$C,"<"&C$1+1)-SUMIFS(movements!$H:$H,movements!$E:$E,$A5,movements!$D:$D,"ISSUE",movements!$C:$C,"<"&C$1+1) -> 61 | D5: =SUMIFS(movements!$H:$H,movements!$E:$E,$A5,movements!$D:$D,"OPENING",movements!$C:$C,"<"&D$1+1)+SUMIFS(movements!$H:$H,movements!$E:$E,$A5,movements!$D:$D,"RECEIPT",movements!$C:$C,"<"&D$1+1)-SUMIFS(movements!$H:$H,movements!$E:$E,$A5,movements!$D:$D,"ISSUE",movements!$C:$C,"<"&D$1+1) -> 48 | E5: =SUMIFS(movements!$H:$H,movements!$E:$E,$A5,movements!$D:$D,"OPENING",movements!$C:$C,"<"&E$1+1)+SUMIFS(movements!$H:$H,movements!$E:$E,$A5,movements!$D:$D,"RECEIPT",movements!$C:$C,"<"&E$1+1)-SUMIFS(movements!$H:$H,movements!$E:$E,$A5,movements!$D:$D,"ISSUE",movements!$C:$C,"<"&E$1+1) -> 43 | F5: =SUMIFS(movements!$H:$H,movements!$E:$E,$A5,movements!$D:$D,"OPENING",movements!$C:$C,"<"&F$1+1)+SUMIFS(movements!$H:$H,movements!$E:$E,$A5,movements!$D:$D,"RECEIPT",movements!$C:$C,"<"&F$1+1)-SUMIFS(movements!$H:$H,movements!$E:$E,$A5,movements!$D:$D,"ISSUE",movements!$C:$C,"<"&F$1+1) -> 22 | G5: =SUMIFS(movements!$H:$H,movements!$E:$E,$A5,movements!$D:$D,"OPENING",movements!$C:$C,"<"&G$1+1)+SUMIFS(movements!$H:$H,movements!$E:$E,$A5,movements!$D:$D,"RECEIPT",movements!$C:$C,"<"&G$1+1)-SUMIFS(movements!$H:$H,movements!$E:$E,$A5,movements!$D:$D,"ISSUE",movements!$C:$C,"<"&G$1+1) -> 15 | H5: =SUMIFS(movements!$H:$H,movements!$E:$E,$A5,movements!$D:$D,"OPENING",movements!$C:$C,"<"&H$1+1)+SUMIFS(movements!$H:$H,movements!$E:$E,$A5,movements!$D:$D,"RECEIPT",movements!$C:$C,"<"&H$1+1)-SUMIFS(movements!$H:$H,movements!$E:$E,$A5,movements!$D:$D,"ISSUE",movements!$C:$C,"<"&H$1+1) -> 4 | I5: =SUMIFS(movements!$H:$H,movements!$E:$E,$A5,movements!$D:$D,"OPENING",movements!$C:$C,"<"&I$1+1)+SUMIFS(movements!$H:$H,movements!$E:$E,$A5,movements!$D:$D,"RECEIPT",movements!$C:$C,"<"&I$1+1)-SUMIFS(movements!$H:$H,movements!$E:$E,$A5,movements!$D:$D,"ISSUE",movements!$C:$C,"<"&I$1+1) -> 57 | ... CM5: =SUMIFS(movements!$H:$H,movements!$E:$E,$A5,movements!$D:$D,"OPENING",movements!$C:$C,"<"&CM$1+1)+SUMIFS(movements!$H:$H,movements!$E:$E,$A5,movements!$D:$D,"RECEIPT",movements!$C:$C,"<"&CM$1+1)-SUMIFS(movements!$H:$H,movements!$E:$E,$A5,movements!$D:$D,"ISSUE",movements!$C:$C,"<"&CM$1+1) -> 17 | CN5: =AVERAGE(B5:CM5) -> 54.7 | CO5: =SUMIFS(movements!$H:$H,movements!$E:$E,$A5,movements!$D:$D,"ISSUE",movements!$C:$C,">="&$B$1,movements!$C:$C,"<"&($CM$1+1)) -> 984 | CP5: =IF(CN5=0,"无法计算",CO5/CN5) -> 17.989031 | CQ5: =IF(CO5=0,"期间无出库",IF(CN5=0,"无法计算",90/CP5)) -> 5.0030488
A6: SKU005 | B6: =SUMIFS(movements!$H:$H,movements!$E:$E,$A6,movements!$D:$D,"OPENING",movements!$C:$C,"<"&B$1+1)+SUMIFS(movements!$H:$H,movements!$E:$E,$A6,movements!$D:$D,"RECEIPT",movements!$C:$C,"<"&B$1+1)-SUMIFS(movements!$H:$H,movements!$E:$E,$A6,movements!$D:$D,"ISSUE",movements!$C:$C,"<"&B$1+1) -> 73 | C6: =SUMIFS(movements!$H:$H,movements!$E:$E,$A6,movements!$D:$D,"OPENING",movements!$C:$C,"<"&C$1+1)+SUMIFS(movements!$H:$H,movements!$E:$E,$A6,movements!$D:$D,"RECEIPT",movements!$C:$C,"<"&C$1+1)-SUMIFS(movements!$H:$H,movements!$E:$E,$A6,movements!$D:$D,"ISSUE",movements!$C:$C,"<"&C$1+1) -> 70 | D6: =SUMIFS(movements!$H:$H,movements!$E:$E,$A6,movements!$D:$D,"OPENING",movements!$C:$C,"<"&D$1+1)+SUMIFS(movements!$H:$H,movements!$E:$E,$A6,movements!$D:$D,"RECEIPT",movements!$C:$C,"<"&D$1+1)-SUMIFS(movements!$H:$H,movements!$E:$E,$A6,movements!$D:$D,"ISSUE",movements!$C:$C,"<"&D$1+1) -> 61 | E6: =SUMIFS(movements!$H:$H,movements!$E:$E,$A6,movements!$D:$D,"OPENING",movements!$C:$C,"<"&E$1+1)+SUMIFS(movements!$H:$H,movements!$E:$E,$A6,movements!$D:$D,"RECEIPT",movements!$C:$C,"<"&E$1+1)-SUMIFS(movements!$H:$H,movements!$E:$E,$A6,movements!$D:$D,"ISSUE",movements!$C:$C,"<"&E$1+1) -> 51 | F6: =SUMIFS(movements!$H:$H,movements!$E:$E,$A6,movements!$D:$D,"OPENING",movements!$C:$C,"<"&F$1+1)+SUMIFS(movements!$H:$H,movements!$E:$E,$A6,movements!$D:$D,"RECEIPT",movements!$C:$C,"<"&F$1+1)-SUMIFS(movements!$H:$H,movements!$E:$E,$A6,movements!$D:$D,"ISSUE",movements!$C:$C,"<"&F$1+1) -> 28 | G6: =SUMIFS(movements!$H:$H,movements!$E:$E,$A6,movements!$D:$D,"OPENING",movements!$C:$C,"<"&G$1+1)+SUMIFS(movements!$H:$H,movements!$E:$E,$A6,movements!$D:$D,"RECEIPT",movements!$C:$C,"<"&G$1+1)-SUMIFS(movements!$H:$H,movements!$E:$E,$A6,movements!$D:$D,"ISSUE",movements!$C:$C,"<"&G$1+1) -> 15 | H6: =SUMIFS(movements!$H:$H,movements!$E:$E,$A6,movements!$D:$D,"OPENING",movements!$C:$C,"<"&H$1+1)+SUMIFS(movements!$H:$H,movements!$E:$E,$A6,movements!$D:$D,"RECEIPT",movements!$C:$C,"<"&H$1+1)-SUMIFS(movements!$H:$H,movements!$E:$E,$A6,movements!$D:$D,"ISSUE",movements!$C:$C,"<"&H$1+1) -> 10 | I6: =SUMIFS(movements!$H:$H,movements!$E:$E,$A6,movements!$D:$D,"OPENING",movements!$C:$C,"<"&I$1+1)+SUMIFS(movements!$H:$H,movements!$E:$E,$A6,movements!$D:$D,"RECEIPT",movements!$C:$C,"<"&I$1+1)-SUMIFS(movements!$H:$H,movements!$E:$E,$A6,movements!$D:$D,"ISSUE",movements!$C:$C,"<"&I$1+1) -> 104 | ... CM6: =SUMIFS(movements!$H:$H,movements!$E:$E,$A6,movements!$D:$D,"OPENING",movements!$C:$C,"<"&CM$1+1)+SUMIFS(movements!$H:$H,movements!$E:$E,$A6,movements!$D:$D,"RECEIPT",movements!$C:$C,"<"&CM$1+1)-SUMIFS(movements!$H:$H,movements!$E:$E,$A6,movements!$D:$D,"ISSUE",movements!$C:$C,"<"&CM$1+1) -> 122 | CN6: =AVERAGE(B6:CM6) -> 102.87778 | CO6: =SUMIFS(movements!$H:$H,movements!$E:$E,$A6,movements!$D:$D,"ISSUE",movements!$C:$C,">="&$B$1,movements!$C:$C,"<"&($CM$1+1)) -> 903 | CP6: =IF(CN6=0,"无法计算",CO6/CN6) -> 8.7774058 | CQ6: =IF(CO6=0,"期间无出库",IF(CN6=0,"无法计算",90/CP6)) -> 10.253599
A7: SKU006 | B7: =SUMIFS(movements!$H:$H,movements!$E:$E,$A7,movements!$D:$D,"OPENING",movements!$C:$C,"<"&B$1+1)+SUMIFS(movements!$H:$H,movements!$E:$E,$A7,movements!$D:$D,"RECEIPT",movements!$C:$C,"<"&B$1+1)-SUMIFS(movements!$H:$H,movements!$E:$E,$A7,movements!$D:$D,"ISSUE",movements!$C:$C,"<"&B$1+1) -> 73 | C7: =SUMIFS(movements!$H:$H,movements!$E:$E,$A7,movements!$D:$D,"OPENING",movements!$C:$C,"<"&C$1+1)+SUMIFS(movements!$H:$H,movements!$E:$E,$A7,movements!$D:$D,"RECEIPT",movements!$C:$C,"<"&C$1+1)-SUMIFS(movements!$H:$H,movements!$E:$E,$A7,movements!$D:$D,"ISSUE",movements!$C:$C,"<"&C$1+1) -> 65 | D7: =SUMIFS(movements!$H:$H,movements!$E:$E,$A7,movements!$D:$D,"OPENING",movements!$C:$C,"<"&D$1+1)+SUMIFS(movements!$H:$H,movements!$E:$E,$A7,movements!$D:$D,"RECEIPT",movements!$C:$C,"<"&D$1+1)-SUMIFS(movements!$H:$H,movements!$E:$E,$A7,movements!$D:$D,"ISSUE",movements!$C:$C,"<"&D$1+1) -> 62 | E7: =SUMIFS(movements!$H:$H,movements!$E:$E,$A7,movements!$D:$D,"OPENING",movements!$C:$C,"<"&E$1+1)+SUMIFS(movements!$H:$H,movements!$E:$E,$A7,movements!$D:$D,"RECEIPT",movements!$C:$C,"<"&E$1+1)-SUMIFS(movements!$H:$H,movements!$E:$E,$A7,movements!$D:$D,"ISSUE",movements!$C:$C,"<"&E$1+1) -> 51 | F7: =SUMIFS(movements!$H:$H,movements!$E:$E,$A7,movements!$D:$D,"OPENING",movements!$C:$C,"<"&F$1+1)+SUMIFS(movements!$H:$H,movements!$E:$E,$A7,movements!$D:$D,"RECEIPT",movements!$C:$C,"<"&F$1+1)-SUMIFS(movements!$H:$H,movements!$E:$E,$A7,movements!$D:$D,"ISSUE",movements!$C:$C,"<"&F$1+1) -> 38 | G7: =SUMIFS(movements!$H:$H,movements!$E:$E,$A7,movements!$D:$D,"OPENING",movements!$C:$C,"<"&G$1+1)+SUMIFS(movements!$H:$H,movements!$E:$E,$A7,movements!$D:$D,"RECEIPT",movements!$C:$C,"<"&G$1+1)-SUMIFS(movements!$H:$H,movements!$E:$E,$A7,movements!$D:$D,"ISSUE",movements!$C:$C,"<"&G$1+1) -> 28 | H7: =SUMIFS(movements!$H:$H,movements!$E:$E,$A7,movements!$D:$D,"OPENING",movements!$C:$C,"<"&H$1+1)+SUMIFS(movements!$H:$H,movements!$E:$E,$A7,movements!$D:$D,"RECEIPT",movements!$C:$C,"<"&H$1+1)-SUMIFS(movements!$H:$H,movements!$E:$E,$A7,movements!$D:$D,"ISSUE",movements!$C:$C,"<"&H$1+1) -> 18 | I7: =SUMIFS(movements!$H:$H,movements!$E:$E,$A7,movements!$D:$D,"OPENING",movements!$C:$C,"<"&I$1+1)+SUMIFS(movements!$H:$H,movements!$E:$E,$A7,movements!$D:$D,"RECEIPT",movements!$C:$C,"<"&I$1+1)-SUMIFS(movements!$H:$H,movements!$E:$E,$A7,movements!$D:$D,"ISSUE",movements!$C:$C,"<"&I$1+1) -> 78 | ... CM7: =SUMIFS(movements!$H:$H,movements!$E:$E,$A7,movements!$D:$D,"OPENING",movements!$C:$C,"<"&CM$1+1)+SUMIFS(movements!$H:$H,movements!$E:$E,$A7,movements!$D:$D,"RECEIPT",movements!$C:$C,"<"&CM$1+1)-SUMIFS(movements!$H:$H,movements!$E:$E,$A7,movements!$D:$D,"ISSUE",movements!$C:$C,"<"&CM$1+1) -> 158 | CN7: =AVERAGE(B7:CM7) -> 108.74444 | CO7: =SUMIFS(movements!$H:$H,movements!$E:$E,$A7,movements!$D:$D,"ISSUE",movements!$C:$C,">="&$B$1,movements!$C:$C,"<"&($CM$1+1)) -> 908 | CP7: =IF(CN7=0,"无法计算",CO7/CN7) -> 8.3498518 | CQ7: =IF(CO7=0,"期间无出库",IF(CN7=0,"无法计算",90/CP7)) -> 10.778634
A8: SKU007 | B8: =SUMIFS(movements!$H:$H,movements!$E:$E,$A8,movements!$D:$D,"OPENING",movements!$C:$C,"<"&B$1+1)+SUMIFS(movements!$H:$H,movements!$E:$E,$A8,movements!$D:$D,"RECEIPT",movements!$C:$C,"<"&B$1+1)-SUMIFS(movements!$H:$H,movements!$E:$E,$A8,movements!$D:$D,"ISSUE",movements!$C:$C,"<"&B$1+1) -> 78 | C8: =SUMIFS(movements!$H:$H,movements!$E:$E,$A8,movements!$D:$D,"OPENING",movements!$C:$C,"<"&C$1+1)+SUMIFS(movements!$H:$H,movements!$E:$E,$A8,movements!$D:$D,"RECEIPT",movements!$C:$C,"<"&C$1+1)-SUMIFS(movements!$H:$H,movements!$E:$E,$A8,movements!$D:$D,"ISSUE",movements!$C:$C,"<"&C$1+1) -> 78 | D8: =SUMIFS(movements!$H:$H,movements!$E:$E,$A8,movements!$D:$D,"OPENING",movements!$C:$C,"<"&D$1+1)+SUMIFS(movements!$H:$H,movements!$E:$E,$A8,movements!$D:$D,"RECEIPT",movements!$C:$C,"<"&D$1+1)-SUMIFS(movements!$H:$H,movements!$E:$E,$A8,movements!$D:$D,"ISSUE",movements!$C:$C,"<"&D$1+1) -> 71 | E8: =SUMIFS(movements!$H:$H,movements!$E:$E,$A8,movements!$D:$D,"OPENING",movements!$C:$C,"<"&E$1+1)+SUMIFS(movements!$H:$H,movements!$E:$E,$A8,movements!$D:$D,"RECEIPT",movements!$C:$C,"<"&E$1+1)-SUMIFS(movements!$H:$H,movements!$E:$E,$A8,movements!$D:$D,"ISSUE",movements!$C:$C,"<"&E$1+1) -> 71 | F8: =SUMIFS(movements!$H:$H,movements!$E:$E,$A8,movements!$D:$D,"OPENING",movements!$C:$C,"<"&F$1+1)+SUMIFS(movements!$H:$H,movements!$E:$E,$A8,movements!$D:$D,"RECEIPT",movements!$C:$C,"<"&F$1+1)-SUMIFS(movements!$H:$H,movements!$E:$E,$A8,movements!$D:$D,"ISSUE",movements!$C:$C,"<"&F$1+1) -> 69 | G8: =SUMIFS(movements!$H:$H,movements!$E:$E,$A8,movements!$D:$D,"OPENING",movements!$C:$C,"<"&G$1+1)+SUMIFS(movements!$H:$H,movements!$E:$E,$A8,movements!$D:$D,"RECEIPT",movements!$C:$C,"<"&G$1+1)-SUMIFS(movements!$H:$H,movements!$E:$E,$A8,movements!$D:$D,"ISSUE",movements!$C:$C,"<"&G$1+1) -> 65 | H8: =SUMIFS(movements!$H:$H,movements!$E:$E,$A8,movements!$D:$D,"OPENING",movements!$C:$C,"<"&H$1+1)+SUMIFS(movements!$H:$H,movements!$E:$E,$A8,movements!$D:$D,"RECEIPT",movements!$C:$C,"<"&H$1+1)-SUMIFS(movements!$H:$H,movements!$E:$E,$A8,movements!$D:$D,"ISSUE",movements!$C:$C,"<"&H$1+1) -> 56 | I8: =SUMIFS(movements!$H:$H,movements!$E:$E,$A8,movements!$D:$D,"OPENING",movements!$C:$C,"<"&I$1+1)+SUMIFS(movements!$H:$H,movements!$E:$E,$A8,movements!$D:$D,"RECEIPT",movements!$C:$C,"<"&I$1+1)-SUMIFS(movements!$H:$H,movements!$E:$E,$A8,movements!$D:$D,"ISSUE",movements!$C:$C,"<"&I$1+1) -> 151 | ... CM8: =SUMIFS(movements!$H:$H,movements!$E:$E,$A8,movements!$D:$D,"OPENING",movements!$C:$C,"<"&CM$1+1)+SUMIFS(movements!$H:$H,movements!$E:$E,$A8,movements!$D:$D,"RECEIPT",movements!$C:$C,"<"&CM$1+1)-SUMIFS(movements!$H:$H,movements!$E:$E,$A8,movements!$D:$D,"ISSUE",movements!$C:$C,"<"&CM$1+1) -> 138 | CN8: =AVERAGE(B8:CM8) -> 124.73333 | CO8: =SUMIFS(movements!$H:$H,movements!$E:$E,$A8,movements!$D:$D,"ISSUE",movements!$C:$C,">="&$B$1,movements!$C:$C,"<"&($CM$1+1)) -> 402 | CP8: =IF(CN8=0,"无法计算",CO8/CN8) -> 3.2228755 | CQ8: =IF(CO8=0,"期间无出库",IF(CN8=0,"无法计算",90/CP8)) -> 27.925373
A9: SKU008 | B9: =SUMIFS(movements!$H:$H,movements!$E:$E,$A9,movements!$D:$D,"OPENING",movements!$C:$C,"<"&B$1+1)+SUMIFS(movements!$H:$H,movements!$E:$E,$A9,movements!$D:$D,"RECEIPT",movements!$C:$C,"<"&B$1+1)-SUMIFS(movements!$H:$H,movements!$E:$E,$A9,movements!$D:$D,"ISSUE",movements!$C:$C,"<"&B$1+1) -> 80 | C9: =SUMIFS(movements!$H:$H,movements!$E:$E,$A9,movements!$D:$D,"OPENING",movements!$C:$C,"<"&C$1+1)+SUMIFS(movements!$H:$H,movements!$E:$E,$A9,movements!$D:$D,"RECEIPT",movements!$C:$C,"<"&C$1+1)-SUMIFS(movements!$H:$H,movements!$E:$E,$A9,movements!$D:$D,"ISSUE",movements!$C:$C,"<"&C$1+1) -> 79 | D9: =SUMIFS(movements!$H:$H,movements!$E:$E,$A9,movements!$D:$D,"OPENING",movements!$C:$C,"<"&D$1+1)+SUMIFS(movements!$H:$H,movements!$E:$E,$A9,movements!$D:$D,"RECEIPT",movements!$C:$C,"<"&D$1+1)-SUMIFS(movements!$H:$H,movements!$E:$E,$A9,movements!$D:$D,"ISSUE",movements!$C:$C,"<"&D$1+1) -> 76 | E9: =SUMIFS(movements!$H:$H,movements!$E:$E,$A9,movements!$D:$D,"OPENING",movements!$C:$C,"<"&E$1+1)+SUMIFS(movements!$H:$H,movements!$E:$E,$A9,movements!$D:$D,"RECEIPT",movements!$C:$C,"<"&E$1+1)-SUMIFS(movements!$H:$H,movements!$E:$E,$A9,movements!$D:$D,"ISSUE",movements!$C:$C,"<"&E$1+1) -> 69 | F9: =SUMIFS(movements!$H:$H,movements!$E:$E,$A9,movements!$D:$D,"OPENING",movements!$C:$C,"<"&F$1+1)+SUMIFS(movements!$H:$H,movements!$E:$E,$A9,movements!$D:$D,"RECEIPT",movements!$C:$C,"<"&F$1+1)-SUMIFS(movements!$H:$H,movements!$E:$E,$A9,movements!$D:$D,"ISSUE",movements!$C:$C,"<"&F$1+1) -> 60 | G9: =SUMIFS(movements!$H:$H,movements!$E:$E,$A9,movements!$D:$D,"OPENING",movements!$C:$C,"<"&G$1+1)+SUMIFS(movements!$H:$H,movements!$E:$E,$A9,movements!$D:$D,"RECEIPT",movements!$C:$C,"<"&G$1+1)-SUMIFS(movements!$H:$H,movements!$E:$E,$A9,movements!$D:$D,"ISSUE",movements!$C:$C,"<"&G$1+1) -> 55 | H9: =SUMIFS(movements!$H:$H,movements!$E:$E,$A9,movements!$D:$D,"OPENING",movements!$C:$C,"<"&H$1+1)+SUMIFS(movements!$H:$H,movements!$E:$E,$A9,movements!$D:$D,"RECEIPT",movements!$C:$C,"<"&H$1+1)-SUMIFS(movements!$H:$H,movements!$E:$E,$A9,movements!$D:$D,"ISSUE",movements!$C:$C,"<"&H$1+1) -> 49 | I9: =SUMIFS(movements!$H:$H,movements!$E:$E,$A9,movements!$D:$D,"OPENING",movements!$C:$C,"<"&I$1+1)+SUMIFS(movements!$H:$H,movements!$E:$E,$A9,movements!$D:$D,"RECEIPT",movements!$C:$C,"<"&I$1+1)-SUMIFS(movements!$H:$H,movements!$E:$E,$A9,movements!$D:$D,"ISSUE",movements!$C:$C,"<"&I$1+1) -> 136 | ... CM9: =SUMIFS(movements!$H:$H,movements!$E:$E,$A9,movements!$D:$D,"OPENING",movements!$C:$C,"<"&CM$1+1)+SUMIFS(movements!$H:$H,movements!$E:$E,$A9,movements!$D:$D,"RECEIPT",movements!$C:$C,"<"&CM$1+1)-SUMIFS(movements!$H:$H,movements!$E:$E,$A9,movements!$D:$D,"ISSUE",movements!$C:$C,"<"&CM$1+1) -> 94 | CN9: =AVERAGE(B9:CM9) -> 125.06667 | CO9: =SUMIFS(movements!$H:$H,movements!$E:$E,$A9,movements!$D:$D,"ISSUE",movements!$C:$C,">="&$B$1,movements!$C:$C,"<"&($CM$1+1)) -> 403 | CP9: =IF(CN9=0,"无法计算",CO9/CN9) -> 3.2222814 | CQ9: =IF(CO9=0,"期间无出库",IF(CN9=0,"无法计算",90/CP9)) -> 27.930521
A10: SKU009 | B10: =SUMIFS(movements!$H:$H,movements!$E:$E,$A10,movements!$D:$D,"OPENING",movements!$C:$C,"<"&B$1+1)+SUMIFS(movements!$H:$H,movements!$E:$E,$A10,movements!$D:$D,"RECEIPT",movements!$C:$C,"<"&B$1+1)-SUMIFS(movements!$H:$H,movements!$E:$E,$A10,movements!$D:$D,"ISSUE",movements!$C:$C,"<"&B$1+1) -> 80 | C10: =SUMIFS(movements!$H:$H,movements!$E:$E,$A10,movements!$D:$D,"OPENING",movements!$C:$C,"<"&C$1+1)+SUMIFS(movements!$H:$H,movements!$E:$E,$A10,movements!$D:$D,"RECEIPT",movements!$C:$C,"<"&C$1+1)-SUMIFS(movements!$H:$H,movements!$E:$E,$A10,movements!$D:$D,"ISSUE",movements!$C:$C,"<"&C$1+1) -> 77 | D10: =SUMIFS(movements!$H:$H,movements!$E:$E,$A10,movements!$D:$D,"OPENING",movements!$C:$C,"<"&D$1+1)+SUMIFS(movements!$H:$H,movements!$E:$E,$A10,movements!$D:$D,"RECEIPT",movements!$C:$C,"<"&D$1+1)-SUMIFS(movements!$H:$H,movements!$E:$E,$A10,movements!$D:$D,"ISSUE",movements!$C:$C,"<"&D$1+1) -> 70 | E10: =SUMIFS(movements!$H:$H,movements!$E:$E,$A10,movements!$D:$D,"OPENING",movements!$C:$C,"<"&E$1+1)+SUMIFS(movements!$H:$H,movements!$E:$E,$A10,movements!$D:$D,"RECEIPT",movements!$C:$C,"<"&E$1+1)-SUMIFS(movements!$H:$H,movements!$E:$E,$A10,movements!$D:$D,"ISSUE",movements!$C:$C,"<"&E$1+1) -> 70 | F10: =SUMIFS(movements!$H:$H,movements!$E:$E,$A10,movements!$D:$D,"OPENING",movements!$C:$C,"<"&F$1+1)+SUMIFS(movements!$H:$H,movements!$E:$E,$A10,movements!$D:$D,"RECEIPT",movements!$C:$C,"<"&F$1+1)-SUMIFS(movements!$H:$H,movements!$E:$E,$A10,movements!$D:$D,"ISSUE",movements!$C:$C,"<"&F$1+1) -> 68 | G10: =SUMIFS(movements!$H:$H,movements!$E:$E,$A10,movements!$D:$D,"OPENING",movements!$C:$C,"<"&G$1+1)+SUMIFS(movements!$H:$H,movements!$E:$E,$A10,movements!$D:$D,"RECEIPT",movements!$C:$C,"<"&G$1+1)-SUMIFS(movements!$H:$H,movements!$E:$E,$A10,movements!$D:$D,"ISSUE",movements!$C:$C,"<"&G$1+1) -> 58 | H10: =SUMIFS(movements!$H:$H,movements!$E:$E,$A10,movements!$D:$D,"OPENING",movements!$C:$C,"<"&H$1+1)+SUMIFS(movements!$H:$H,movements!$E:$E,$A10,movements!$D:$D,"RECEIPT",movements!$C:$C,"<"&H$1+1)-SUMIFS(movements!$H:$H,movements!$E:$E,$A10,movements!$D:$D,"ISSUE",movements!$C:$C,"<"&H$1+1) -> 48 | I10: =SUMIFS(movements!$H:$H,movements!$E:$E,$A10,movements!$D:$D,"OPENING",movements!$C:$C,"<"&I$1+1)+SUMIFS(movements!$H:$H,movements!$E:$E,$A10,movements!$D:$D,"RECEIPT",movements!$C:$C,"<"&I$1+1)-SUMIFS(movements!$H:$H,movements!$E:$E,$A10,movements!$D:$D,"ISSUE",movements!$C:$C,"<"&I$1+1) -> 115 | ... CM10: =SUMIFS(movements!$H:$H,movements!$E:$E,$A10,movements!$D:$D,"OPENING",movements!$C:$C,"<"&CM$1+1)+SUMIFS(movements!$H:$H,movements!$E:$E,$A10,movements!$D:$D,"RECEIPT",movements!$C:$C,"<"&CM$1+1)-SUMIFS(movements!$H:$H,movements!$E:$E,$A10,movements!$D:$D,"ISSUE",movements!$C:$C,"<"&CM$1+1) -> 140 | CN10: =AVERAGE(B10:CM10) -> 117.72222 | CO10: =SUMIFS(movements!$H:$H,movements!$E:$E,$A10,movements!$D:$D,"ISSUE",movements!$C:$C,">="&$B$1,movements!$C:$C,"<"&($CM$1+1)) -> 477 | CP10: =IF(CN10=0,"无法计算",CO10/CN10) -> 4.0519113 | CQ10: =IF(CO10=0,"期间无出库",IF(CN10=0,"无法计算",90/CP10)) -> 22.21174
A11: SKU010 | B11: =SUMIFS(movements!$H:$H,movements!$E:$E,$A11,movements!$D:$D,"OPENING",movements!$C:$C,"<"&B$1+1)+SUMIFS(movements!$H:$H,movements!$E:$E,$A11,movements!$D:$D,"RECEIPT",movements!$C:$C,"<"&B$1+1)-SUMIFS(movements!$H:$H,movements!$E:$E,$A11,movements!$D:$D,"ISSUE",movements!$C:$C,"<"&B$1+1) -> 80 | C11: =SUMIFS(movements!$H:$H,movements!$E:$E,$A11,movements!$D:$D,"OPENING",movements!$C:$C,"<"&C$1+1)+SUMIFS(movements!$H:$H,movements!$E:$E,$A11,movements!$D:$D,"RECEIPT",movements!$C:$C,"<"&C$1+1)-SUMIFS(movements!$H:$H,movements!$E:$E,$A11,movements!$D:$D,"ISSUE",movements!$C:$C,"<"&C$1+1) -> 80 | D11: =SUMIFS(movements!$H:$H,movements!$E:$E,$A11,movements!$D:$D,"OPENING",movements!$C:$C,"<"&D$1+1)+SUMIFS(movements!$H:$H,movements!$E:$E,$A11,movements!$D:$D,"RECEIPT",movements!$C:$C,"<"&D$1+1)-SUMIFS(movements!$H:$H,movements!$E:$E,$A11,movements!$D:$D,"ISSUE",movements!$C:$C,"<"&D$1+1) -> 80 | E11: =SUMIFS(movements!$H:$H,movements!$E:$E,$A11,movements!$D:$D,"OPENING",movements!$C:$C,"<"&E$1+1)+SUMIFS(movements!$H:$H,movements!$E:$E,$A11,movements!$D:$D,"RECEIPT",movements!$C:$C,"<"&E$1+1)-SUMIFS(movements!$H:$H,movements!$E:$E,$A11,movements!$D:$D,"ISSUE",movements!$C:$C,"<"&E$1+1) -> 80 | F11: =SUMIFS(movements!$H:$H,movements!$E:$E,$A11,movements!$D:$D,"OPENING",movements!$C:$C,"<"&F$1+1)+SUMIFS(movements!$H:$H,movements!$E:$E,$A11,movements!$D:$D,"RECEIPT",movements!$C:$C,"<"&F$1+1)-SUMIFS(movements!$H:$H,movements!$E:$E,$A11,movements!$D:$D,"ISSUE",movements!$C:$C,"<"&F$1+1) -> 80 | G11: =SUMIFS(movements!$H:$H,movements!$E:$E,$A11,movements!$D:$D,"OPENING",movements!$C:$C,"<"&G$1+1)+SUMIFS(movements!$H:$H,movements!$E:$E,$A11,movements!$D:$D,"RECEIPT",movements!$C:$C,"<"&G$1+1)-SUMIFS(movements!$H:$H,movements!$E:$E,$A11,movements!$D:$D,"ISSUE",movements!$C:$C,"<"&G$1+1) -> 80 | H11: =SUMIFS(movements!$H:$H,movements!$E:$E,$A11,movements!$D:$D,"OPENING",movements!$C:$C,"<"&H$1+1)+SUMIFS(movements!$H:$H,movements!$E:$E,$A11,movements!$D:$D,"RECEIPT",movements!$C:$C,"<"&H$1+1)-SUMIFS(movements!$H:$H,movements!$E:$E,$A11,movements!$D:$D,"ISSUE",movements!$C:$C,"<"&H$1+1) -> 80 | I11: =SUMIFS(movements!$H:$H,movements!$E:$E,$A11,movements!$D:$D,"OPENING",movements!$C:$C,"<"&I$1+1)+SUMIFS(movements!$H:$H,movements!$E:$E,$A11,movements!$D:$D,"RECEIPT",movements!$C:$C,"<"&I$1+1)-SUMIFS(movements!$H:$H,movements!$E:$E,$A11,movements!$D:$D,"ISSUE",movements!$C:$C,"<"&I$1+1) -> 166 | ... CM11: =SUMIFS(movements!$H:$H,movements!$E:$E,$A11,movements!$D:$D,"OPENING",movements!$C:$C,"<"&CM$1+1)+SUMIFS(movements!$H:$H,movements!$E:$E,$A11,movements!$D:$D,"RECEIPT",movements!$C:$C,"<"&CM$1+1)-SUMIFS(movements!$H:$H,movements!$E:$E,$A11,movements!$D:$D,"ISSUE",movements!$C:$C,"<"&CM$1+1) -> 237 | CN11: =AVERAGE(B11:CM11) -> 180.61111 | CO11: =SUMIFS(movements!$H:$H,movements!$E:$E,$A11,movements!$D:$D,"ISSUE",movements!$C:$C,">="&$B$1,movements!$C:$C,"<"&($CM$1+1)) -> 0 | CP11: =IF(CN11=0,"无法计算",CO11/CN11) -> 0 | CQ11: =IF(CO11=0,"期间无出库",IF(CN11=0,"无法计算",90/CP11)) -> 期间无出库
A12: SKU011 | B12: =SUMIFS(movements!$H:$H,movements!$E:$E,$A12,movements!$D:$D,"OPENING",movements!$C:$C,"<"&B$1+1)+SUMIFS(movements!$H:$H,movements!$E:$E,$A12,movements!$D:$D,"RECEIPT",movements!$C:$C,"<"&B$1+1)-SUMIFS(movements!$H:$H,movements!$E:$E,$A12,movements!$D:$D,"ISSUE",movements!$C:$C,"<"&B$1+1) -> 71 | C12: =SUMIFS(movements!$H:$H,movements!$E:$E,$A12,movements!$D:$D,"OPENING",movements!$C:$C,"<"&C$1+1)+SUMIFS(movements!$H:$H,movements!$E:$E,$A12,movements!$D:$D,"RECEIPT",movements!$C:$C,"<"&C$1+1)-SUMIFS(movements!$H:$H,movements!$E:$E,$A12,movements!$D:$D,"ISSUE",movements!$C:$C,"<"&C$1+1) -> 66 | D12: =SUMIFS(movements!$H:$H,movements!$E:$E,$A12,movements!$D:$D,"OPENING",movements!$C:$C,"<"&D$1+1)+SUMIFS(movements!$H:$H,movements!$E:$E,$A12,movements!$D:$D,"RECEIPT",movements!$C:$C,"<"&D$1+1)-SUMIFS(movements!$H:$H,movements!$E:$E,$A12,movements!$D:$D,"ISSUE",movements!$C:$C,"<"&D$1+1) -> 60 | E12: =SUMIFS(movements!$H:$H,movements!$E:$E,$A12,movements!$D:$D,"OPENING",movements!$C:$C,"<"&E$1+1)+SUMIFS(movements!$H:$H,movements!$E:$E,$A12,movements!$D:$D,"RECEIPT",movements!$C:$C,"<"&E$1+1)-SUMIFS(movements!$H:$H,movements!$E:$E,$A12,movements!$D:$D,"ISSUE",movements!$C:$C,"<"&E$1+1) -> 54 | F12: =SUMIFS(movements!$H:$H,movements!$E:$E,$A12,movements!$D:$D,"OPENING",movements!$C:$C,"<"&F$1+1)+SUMIFS(movements!$H:$H,movements!$E:$E,$A12,movements!$D:$D,"RECEIPT",movements!$C:$C,"<"&F$1+1)-SUMIFS(movements!$H:$H,movements!$E:$E,$A12,movements!$D:$D,"ISSUE",movements!$C:$C,"<"&F$1+1) -> 50 | G12: =SUMIFS(movements!$H:$H,movements!$E:$E,$A12,movements!$D:$D,"OPENING",movements!$C:$C,"<"&G$1+1)+SUMIFS(movements!$H:$H,movements!$E:$E,$A12,movements!$D:$D,"RECEIPT",movements!$C:$C,"<"&G$1+1)-SUMIFS(movements!$H:$H,movements!$E:$E,$A12,movements!$D:$D,"ISSUE",movements!$C:$C,"<"&G$1+1) -> 47 | H12: =SUMIFS(movements!$H:$H,movements!$E:$E,$A12,movements!$D:$D,"OPENING",movements!$C:$C,"<"&H$1+1)+SUMIFS(movements!$H:$H,movements!$E:$E,$A12,movements!$D:$D,"RECEIPT",movements!$C:$C,"<"&H$1+1)-SUMIFS(movements!$H:$H,movements!$E:$E,$A12,movements!$D:$D,"ISSUE",movements!$C:$C,"<"&H$1+1) -> 37 | I12: =SUMIFS(movements!$H:$H,movements!$E:$E,$A12,movements!$D:$D,"OPENING",movements!$C:$C,"<"&I$1+1)+SUMIFS(movements!$H:$H,movements!$E:$E,$A12,movements!$D:$D,"RECEIPT",movements!$C:$C,"<"&I$1+1)-SUMIFS(movements!$H:$H,movements!$E:$E,$A12,movements!$D:$D,"ISSUE",movements!$C:$C,"<"&I$1+1) -> 114 | ... CM12: =SUMIFS(movements!$H:$H,movements!$E:$E,$A12,movements!$D:$D,"OPENING",movements!$C:$C,"<"&CM$1+1)+SUMIFS(movements!$H:$H,movements!$E:$E,$A12,movements!$D:$D,"RECEIPT",movements!$C:$C,"<"&CM$1+1)-SUMIFS(movements!$H:$H,movements!$E:$E,$A12,movements!$D:$D,"ISSUE",movements!$C:$C,"<"&CM$1+1) -> 116 | CN12: =AVERAGE(B12:CM12) -> 124.25556 | CO12: =SUMIFS(movements!$H:$H,movements!$E:$E,$A12,movements!$D:$D,"ISSUE",movements!$C:$C,">="&$B$1,movements!$C:$C,"<"&($CM$1+1)) -> 463 | CP12: =IF(CN12=0,"无法计算",CO12/CN12) -> 3.7261915 | CQ12: =IF(CO12=0,"期间无出库",IF(CN12=0,"无法计算",90/CP12)) -> 24.153348
A13: SKU012 | B13: =SUMIFS(movements!$H:$H,movements!$E:$E,$A13,movements!$D:$D,"OPENING",movements!$C:$C,"<"&B$1+1)+SUMIFS(movements!$H:$H,movements!$E:$E,$A13,movements!$D:$D,"RECEIPT",movements!$C:$C,"<"&B$1+1)-SUMIFS(movements!$H:$H,movements!$E:$E,$A13,movements!$D:$D,"ISSUE",movements!$C:$C,"<"&B$1+1) -> 79 | C13: =SUMIFS(movements!$H:$H,movements!$E:$E,$A13,movements!$D:$D,"OPENING",movements!$C:$C,"<"&C$1+1)+SUMIFS(movements!$H:$H,movements!$E:$E,$A13,movements!$D:$D,"RECEIPT",movements!$C:$C,"<"&C$1+1)-SUMIFS(movements!$H:$H,movements!$E:$E,$A13,movements!$D:$D,"ISSUE",movements!$C:$C,"<"&C$1+1) -> 74 | D13: =SUMIFS(movements!$H:$H,movements!$E:$E,$A13,movements!$D:$D,"OPENING",movements!$C:$C,"<"&D$1+1)+SUMIFS(movements!$H:$H,movements!$E:$E,$A13,movements!$D:$D,"RECEIPT",movements!$C:$C,"<"&D$1+1)-SUMIFS(movements!$H:$H,movements!$E:$E,$A13,movements!$D:$D,"ISSUE",movements!$C:$C,"<"&D$1+1) -> 70 | E13: =SUMIFS(movements!$H:$H,movements!$E:$E,$A13,movements!$D:$D,"OPENING",movements!$C:$C,"<"&E$1+1)+SUMIFS(movements!$H:$H,movements!$E:$E,$A13,movements!$D:$D,"RECEIPT",movements!$C:$C,"<"&E$1+1)-SUMIFS(movements!$H:$H,movements!$E:$E,$A13,movements!$D:$D,"ISSUE",movements!$C:$C,"<"&E$1+1) -> 69 | F13: =SUMIFS(movements!$H:$H,movements!$E:$E,$A13,movements!$D:$D,"OPENING",movements!$C:$C,"<"&F$1+1)+SUMIFS(movements!$H:$H,movements!$E:$E,$A13,movements!$D:$D,"RECEIPT",movements!$C:$C,"<"&F$1+1)-SUMIFS(movements!$H:$H,movements!$E:$E,$A13,movements!$D:$D,"ISSUE",movements!$C:$C,"<"&F$1+1) -> 64 | G13: =SUMIFS(movements!$H:$H,movements!$E:$E,$A13,movements!$D:$D,"OPENING",movements!$C:$C,"<"&G$1+1)+SUMIFS(movements!$H:$H,movements!$E:$E,$A13,movements!$D:$D,"RECEIPT",movements!$C:$C,"<"&G$1+1)-SUMIFS(movements!$H:$H,movements!$E:$E,$A13,movements!$D:$D,"ISSUE",movements!$C:$C,"<"&G$1+1) -> 57 | H13: =SUMIFS(movements!$H:$H,movements!$E:$E,$A13,movements!$D:$D,"OPENING",movements!$C:$C,"<"&H$1+1)+SUMIFS(movements!$H:$H,movements!$E:$E,$A13,movements!$D:$D,"RECEIPT",movements!$C:$C,"<"&H$1+1)-SUMIFS(movements!$H:$H,movements!$E:$E,$A13,movements!$D:$D,"ISSUE",movements!$C:$C,"<"&H$1+1) -> 54 | I13: =SUMIFS(movements!$H:$H,movements!$E:$E,$A13,movements!$D:$D,"OPENING",movements!$C:$C,"<"&I$1+1)+SUMIFS(movements!$H:$H,movements!$E:$E,$A13,movements!$D:$D,"RECEIPT",movements!$C:$C,"<"&I$1+1)-SUMIFS(movements!$H:$H,movements!$E:$E,$A13,movements!$D:$D,"ISSUE",movements!$C:$C,"<"&I$1+1) -> 113 | ... CM13: =SUMIFS(movements!$H:$H,movements!$E:$E,$A13,movements!$D:$D,"OPENING",movements!$C:$C,"<"&CM$1+1)+SUMIFS(movements!$H:$H,movements!$E:$E,$A13,movements!$D:$D,"RECEIPT",movements!$C:$C,"<"&CM$1+1)-SUMIFS(movements!$H:$H,movements!$E:$E,$A13,movements!$D:$D,"ISSUE",movements!$C:$C,"<"&CM$1+1) -> 163 | CN13: =AVERAGE(B13:CM13) -> 128.62222 | CO13: =SUMIFS(movements!$H:$H,movements!$E:$E,$A13,movements!$D:$D,"ISSUE",movements!$C:$C,">="&$B$1,movements!$C:$C,"<"&($CM$1+1)) -> 369 | CP13: =IF(CN13=0,"无法计算",CO13/CN13) -> 2.8688666 | CQ13: =IF(CO13=0,"期间无出库",IF(CN13=0,"无法计算",90/CP13)) -> 31.371274
... A31: SKU030 | B31: =SUMIFS(movements!$H:$H,movements!$E:$E,$A31,movements!$D:$D,"OPENING",movements!$C:$C,"<"&B$1+1)+SUMIFS(movements!$H:$H,movements!$E:$E,$A31,movements!$D:$D,"RECEIPT",movements!$C:$C,"<"&B$1+1)-SUMIFS(movements!$H:$H,movements!$E:$E,$A31,movements!$D:$D,"ISSUE",movements!$C:$C,"<"&B$1+1) -> 240 | C31: =SUMIFS(movements!$H:$H,movements!$E:$E,$A31,movements!$D:$D,"OPENING",movements!$C:$C,"<"&C$1+1)+SUMIFS(movements!$H:$H,movements!$E:$E,$A31,movements!$D:$D,"RECEIPT",movements!$C:$C,"<"&C$1+1)-SUMIFS(movements!$H:$H,movements!$E:$E,$A31,movements!$D:$D,"ISSUE",movements!$C:$C,"<"&C$1+1) -> 240 | D31: =SUMIFS(movements!$H:$H,movements!$E:$E,$A31,movements!$D:$D,"OPENING",movements!$C:$C,"<"&D$1+1)+SUMIFS(movements!$H:$H,movements!$E:$E,$A31,movements!$D:$D,"RECEIPT",movements!$C:$C,"<"&D$1+1)-SUMIFS(movements!$H:$H,movements!$E:$E,$A31,movements!$D:$D,"ISSUE",movements!$C:$C,"<"&D$1+1) -> 240 | E31: =SUMIFS(movements!$H:$H,movements!$E:$E,$A31,movements!$D:$D,"OPENING",movements!$C:$C,"<"&E$1+1)+SUMIFS(movements!$H:$H,movements!$E:$E,$A31,movements!$D:$D,"RECEIPT",movements!$C:$C,"<"&E$1+1)-SUMIFS(movements!$H:$H,movements!$E:$E,$A31,movements!$D:$D,"ISSUE",movements!$C:$C,"<"&E$1+1) -> 240 | F31: =SUMIFS(movements!$H:$H,movements!$E:$E,$A31,movements!$D:$D,"OPENING",movements!$C:$C,"<"&F$1+1)+SUMIFS(movements!$H:$H,movements!$E:$E,$A31,movements!$D:$D,"RECEIPT",movements!$C:$C,"<"&F$1+1)-SUMIFS(movements!$H:$H,movements!$E:$E,$A31,movements!$D:$D,"ISSUE",movements!$C:$C,"<"&F$1+1) -> 240 | G31: =SUMIFS(movements!$H:$H,movements!$E:$E,$A31,movements!$D:$D,"OPENING",movements!$C:$C,"<"&G$1+1)+SUMIFS(movements!$H:$H,movements!$E:$E,$A31,movements!$D:$D,"RECEIPT",movements!$C:$C,"<"&G$1+1)-SUMIFS(movements!$H:$H,movements!$E:$E,$A31,movements!$D:$D,"ISSUE",movements!$C:$C,"<"&G$1+1) -> 240 | H31: =SUMIFS(movements!$H:$H,movements!$E:$E,$A31,movements!$D:$D,"OPENING",movements!$C:$C,"<"&H$1+1)+SUMIFS(movements!$H:$H,movements!$E:$E,$A31,movements!$D:$D,"RECEIPT",movements!$C:$C,"<"&H$1+1)-SUMIFS(movements!$H:$H,movements!$E:$E,$A31,movements!$D:$D,"ISSUE",movements!$C:$C,"<"&H$1+1) -> 240 | I31: =SUMIFS(movements!$H:$H,movements!$E:$E,$A31,movements!$D:$D,"OPENING",movements!$C:$C,"<"&I$1+1)+SUMIFS(movements!$H:$H,movements!$E:$E,$A31,movements!$D:$D,"RECEIPT",movements!$C:$C,"<"&I$1+1)-SUMIFS(movements!$H:$H,movements!$E:$E,$A31,movements!$D:$D,"ISSUE",movements!$C:$C,"<"&I$1+1) -> 240 | ... CM31: =SUMIFS(movements!$H:$H,movements!$E:$E,$A31,movements!$D:$D,"OPENING",movements!$C:$C,"<"&CM$1+1)+SUMIFS(movements!$H:$H,movements!$E:$E,$A31,movements!$D:$D,"RECEIPT",movements!$C:$C,"<"&CM$1+1)-SUMIFS(movements!$H:$H,movements!$E:$E,$A31,movements!$D:$D,"ISSUE",movements!$C:$C,"<"&CM$1+1) -> 240 | CN31: =AVERAGE(B31:CM31) -> 240 | CO31: =SUMIFS(movements!$H:$H,movements!$E:$E,$A31,movements!$D:$D,"ISSUE",movements!$C:$C,">="&$B$1,movements!$C:$C,"<"&($CM$1+1)) -> 0 | CP31: =IF(CN31=0,"无法计算",CO31/CN31) -> 0 | CQ31: =IF(CO31=0,"期间无出库",IF(CN31=0,"无法计算",90/CP31)) -> 期间无出库

Sheet 库存汇总
C6: 统计日期：2026-09-06 | D6: 金额单位：元
C7: 行标签 | D7: 求和项:库存金额
C8: 冻结待检 | D8: 2315.39
C9: 临期 | D9: 4384.34
C10: 无库存 | D10: 0
C11: 已到期/过期 | D11: 2324
C12: 正常 | D12: 141932.52
C13: 总计 | D13: 150956.25

Sheet 批次库存
A1: 批次编号 | B1: SKU | C1: 商品名称 | D1: 货位 | E1: 到期日 | F1: 质量状态 | G1: 期初数量 | H1: 入库数量 | I1: 出库数量 | J1: 期末库存 | K1: 单价 | L1: 库存金额 | M1: 剩余有效天数 | N1: 临期预警天数 | O1: 库存状态 | P1: 可出库数量
A2: B0001 | B2: =VLOOKUP(A2,batches!A:B,2,0) -> SKU001 | C2: =VLOOKUP(批次库存!B2,products!A:B,2,0) -> 茉莉绿茶 | D2: =VLOOKUP(A2,batches!A:C,3,0) -> L001 | E2: =VLOOKUP(A2,batches!A:E,5,0) -> 46282 | F2: =VLOOKUP(A2,batches!A:G,7,0) -> RELEASED | G2: =SUMIFS(movements!H:H,movements!F:F,批次库存!A2,movements!D:D,"OPENING") -> 80 | H2: =SUMIFS(movements!H:H,movements!F:F,批次库存!A2,movements!D:D,"RECEIPT") -> 0 | I2: =SUMIFS(movements!H:H,movements!F:F,批次库存!A2,movements!D:D,"ISSUE") -> 80 | J2: =G2+H2-I2 -> 0 | K2: =VLOOKUP(表2[[#This Row],[SKU]],products!A:F,6,0) -> 79.76 | L2: =J2*表2[[#This Row],[单价]] -> 0 | M2: =E2-DATE(2026,9,6) -> 11 | N2: =VLOOKUP(表2[[#This Row],[SKU]],products!A:H,8,0) -> 30 | O2: =IF(表2[[#This Row],[期末库存]]=0,"无库存",IF(表2[[#This Row],[剩余有效天数]]<=0,"已到期/过期",IF(表2[[#This Row],[质量状态]]="HOLD","冻结待检",IF(表2[[#This Row],[剩余有效天数]]<=表2[[#This Row],[临期预警天数]],"临期","正常")))) -> 无库存 | P2: =IF(AND(F2="RELEASED",M2>0),J2,0) -> 0
A3: B0002 | B3: =VLOOKUP(A3,batches!A:B,2,0) -> SKU002 | C3: =VLOOKUP(批次库存!B3,products!A:B,2,0) -> 红茶 | D3: =VLOOKUP(A3,batches!A:C,3,0) -> L002 | E3: =VLOOKUP(A3,batches!A:E,5,0) -> 46252 | F3: =VLOOKUP(A3,batches!A:G,7,0) -> RELEASED | G3: =SUMIFS(movements!H:H,movements!F:F,批次库存!A3,movements!D:D,"OPENING") -> 80 | H3: =SUMIFS(movements!H:H,movements!F:F,批次库存!A3,movements!D:D,"RECEIPT") -> 0 | I3: =SUMIFS(movements!H:H,movements!F:F,批次库存!A3,movements!D:D,"ISSUE") -> 80 | J3: =G3+H3-I3 -> 0 | K3: =VLOOKUP(表2[[#This Row],[SKU]],products!A:F,6,0) -> 78.48 | L3: =J3*表2[[#This Row],[单价]] -> 0 | M3: =E3-DATE(2026,9,6) -> -19 | N3: =VLOOKUP(表2[[#This Row],[SKU]],products!A:H,8,0) -> 30 | O3: =IF(表2[[#This Row],[期末库存]]=0,"无库存",IF(表2[[#This Row],[剩余有效天数]]<=0,"已到期/过期",IF(表2[[#This Row],[质量状态]]="HOLD","冻结待检",IF(表2[[#This Row],[剩余有效天数]]<=表2[[#This Row],[临期预警天数]],"临期","正常")))) -> 无库存 | P3: =IF(AND(F3="RELEASED",M3>0),J3,0) -> 0
A4: B0003 | B4: =VLOOKUP(A4,batches!A:B,2,0) -> SKU003 | C4: =VLOOKUP(批次库存!B4,products!A:B,2,0) -> 乌龙茶 | D4: =VLOOKUP(A4,batches!A:C,3,0) -> L003 | E4: =VLOOKUP(A4,batches!A:E,5,0) -> 46252 | F4: =VLOOKUP(A4,batches!A:G,7,0) -> RELEASED | G4: =SUMIFS(movements!H:H,movements!F:F,批次库存!A4,movements!D:D,"OPENING") -> 80 | H4: =SUMIFS(movements!H:H,movements!F:F,批次库存!A4,movements!D:D,"RECEIPT") -> 0 | I4: =SUMIFS(movements!H:H,movements!F:F,批次库存!A4,movements!D:D,"ISSUE") -> 80 | J4: =G4+H4-I4 -> 0 | K4: =VLOOKUP(表2[[#This Row],[SKU]],products!A:F,6,0) -> 41.99 | L4: =J4*表2[[#This Row],[单价]] -> 0 | M4: =E4-DATE(2026,9,6) -> -19 | N4: =VLOOKUP(表2[[#This Row],[SKU]],products!A:H,8,0) -> 30 | O4: =IF(表2[[#This Row],[期末库存]]=0,"无库存",IF(表2[[#This Row],[剩余有效天数]]<=0,"已到期/过期",IF(表2[[#This Row],[质量状态]]="HOLD","冻结待检",IF(表2[[#This Row],[剩余有效天数]]<=表2[[#This Row],[临期预警天数]],"临期","正常")))) -> 无库存 | P4: =IF(AND(F4="RELEASED",M4>0),J4,0) -> 0
